Workbook

Sheet Leeme
A1: Carnitas — Costeo del menú para Boyacá
A3: CÓMO USAR ESTE ARCHIVO
A4: 1. Hoja 'Insumos': cambia los precios en AZUL con fondo amarillo por las cotizaciones de tus proveedores.
A5: 2. Hoja 'Salsa Carnitas': receta del lote de 1 kg; su costo por kg pasa solo a 'Insumos'.
A6: 3. Hoja 'Fichas técnicas': gramajes de cada plato (editables en azul). Los costos se calculan solos.
A7: 4. Hoja 'Resumen': precio de venta (azul), % de costo, ganancia y precios sugeridos. Ajusta el % objetivo y la comisión de apps.
A8: 5. Hoja 'Extras': adiciones, combo y frasco de salsa, con su margen.
A10: CÓDIGO DE COLORES
A11: Texto azul con fondo amarillo = dato que puedes editar. Texto negro = fórmula. Texto verde = viene de otra hoja.
A13: IMPORTANTE SOBRE LOS PRECIOS
A14: Solo el pernil de cerdo ($17.000/kg) y la papa criolla ($5.192/kg) son datos de Tunja (Agronegocios, julio 2026).
A15: Todos los demás precios son ESTIMADOS típicos de Colombia: reemplázalos con tus cotizaciones antes de fijar precios de venta.
... A40: Papa criolla Tunja: https://www.agronegocios.co/precios/papa-criolla/andina/boyaca/tunja

Sheet Resumen
A1: Resumen del menú — precios y márgenes
A3: % de costo objetivo | B3: 0.35 | C3: Rango sano: 33%–38% en platos personales; hasta ~40% en platos para compartir.
A4: Comisión de apps (Rappi/DiDi) | B4: 0.25 | C4: Estimado: suele estar entre 20% y 30%. Confírmalo con cada plataforma.
A6: Plato | B6: Tamaño | C6: Peso (g) | D6: Costo (COP) | E6: Precio de venta (COP) | F6: % costo | G6: Ganancia bruta (COP) | H6: Precio sugerido por % objetivo | I6: Precio sugerido en apps
A7: La Clásica Carnitas | B7: Personal | C7: ='Fichas técnicas'!C16 -> 470 | D7: ='Fichas técnicas'!D16 -> 7396.9188 | E7: 18900 | F7: =IF(E7=0,0,D7/E7) -> 0.39137136 | G7: =E7-D7 -> 11503.081 | H7: =IF($B$3=0,0,CEILING(D7/$B$3,1000)-100) -> 21900 | I7: =IF($B$4>=1,0,CEILING(E7/(1-$B$4),1000)-100) -> 25900
A8: La Clásica Carnitas | B8: Para compartir (2) | C8: ='Fichas técnicas'!E16 -> 940 | D8: ='Fichas técnicas'!F16 -> 14293.838 | E8: 36900 | F8: =IF(E8=0,0,D8/E8) -> 0.38736687 | G8: =E8-D8 -> 22606.162 | H8: =IF($B$3=0,0,CEILING(D8/$B$3,1000)-100) -> 40900 | I8: =IF($B$4>=1,0,CEILING(E8/(1-$B$4),1000)-100) -> 49900
A9: La Gringa Carnitas | B9: Personal | C9: ='Fichas técnicas'!C32 -> 510 | D9: ='Fichas técnicas'!D32 -> 9339.7254 | E9: 26900 | F9: =IF(E9=0,0,D9/E9) -> 0.34720169 | G9: =E9-D9 -> 17560.275 | H9: =IF($B$3=0,0,CEILING(D9/$B$3,1000)-100) -> 26900 | I9: =IF($B$4>=1,0,CEILING(E9/(1-$B$4),1000)-100) -> 35900
A10: La Gringa Carnitas | B10: Para compartir (2) | C10: ='Fichas técnicas'!E32 -> 1020 | D10: ='Fichas técnicas'!F32 -> 18179.451 | E10: 47900 | F10: =IF(E10=0,0,D10/E10) -> 0.37952924 | G10: =E10-D10 -> 29720.549 | H10: =IF($B$3=0,0,CEILING(D10/$B$3,1000)-100) -> 51900 | I10: =IF($B$4>=1,0,CEILING(E10/(1-$B$4),1000)-100) -> 63900
A11: La Boyacense | B11: Personal | C11: ='Fichas técnicas'!C49 -> 610 | D11: ='Fichas técnicas'!D49 -> 10331.869 | E11: 27900 | F11: =IF(E11=0,0,D11/E11) -> 0.37031788 | G11: =E11-D11 -> 17568.131 | H11: =IF($B$3=0,0,CEILING(D11/$B$3,1000)-100) -> 29900 | I11: =IF($B$4>=1,0,CEILING(E11/(1-$B$4),1000)-100) -> 37900
A12: La Boyacense | B12: Para compartir (2) | C12: ='Fichas técnicas'!E49 -> 1220 | D12: ='Fichas técnicas'!F49 -> 20163.738 | E12: 49900 | F12: =IF(E12=0,0,D12/E12) -> 0.40408292 | G12: =E12-D12 -> 29736.262 | H12: =IF($B$3=0,0,CEILING(D12/$B$3,1000)-100) -> 57900 | I12: =IF($B$4>=1,0,CEILING(E12/(1-$B$4),1000)-100) -> 66900
A14: Notas
A15: • Los precios sugeridos redondean hacia arriba y terminan en 900 (ej. $18.900), como se acostumbra en Colombia.
A16: • Ganancia bruta = precio − costo de comida y empaque. No incluye arriendo, nómina ni servicios.
A17: • Combo Clásica + gaseosa y extras: ver la hoja 'Extras'.

Sheet Fichas técnicas
A1: Fichas técnicas — gramajes y costo por plato
A3: 1. La Clásica Carnitas
A4: Motor de recompra: precio de entrada, salchipapa mejorada con carnitas.
A5: Ingrediente | B5: Unidad | C5: Personal: cantidad | D5: Personal: costo (COP) | E5: Compartir: cantidad | F5: Compartir: costo (COP) | G5: Costo unitario (COP)
A6: Papa pastusa fresca (francesa) | B6: =IF(INDEX(Insumos!$B$5:$B$25,MATCH(A6,Insumos!$A$5:$A$25,0))="kg","g","und") -> g | C6: 250 | D6: =C6*G6 -> 727.27273 | E6: 500 | F6: =E6*G6 -> 1454.5455 | G6: =INDEX(Insumos!$E$5:$E$25,MATCH(A6,Insumos!$A$5:$A$25,0)) -> 2.9090909
A7: Aceite de fritura (porción) | B7: =IF(INDEX(Insumos!$B$5:$B$25,MATCH(A7,Insumos!$A$5:$A$25,0))="kg","g","und") -> und | C7: 1 | D7: =C7*G7 -> 500 | E7: 2 | F7: =E7*G7 -> 1000 | G7: =INDEX(Insumos!$E$5:$E$25,MATCH(A7,Insumos!$A$5:$A$25,0)) -> 500
A8: Carnitas (pernil sin hueso) | B8: =IF(INDEX(Insumos!$B$5:$B$25,MATCH(A8,Insumos!$A$5:$A$25,0))="kg","g","und") -> g | C8: 60 | D8: =C8*G8 -> 2040 | E8: 120 | F8: =E8*G8 -> 4080 | G8: =INDEX(Insumos!$E$5:$E$25,MATCH(A8,Insumos!$A$5:$A$25,0)) -> 34
A9: Salchicha | B9: =IF(INDEX(Insumos!$B$5:$B$25,MATCH(A9,Insumos!$A$5:$A$25,0))="kg","g","und") -> g | C9: 50 | D9: =C9*G9 -> 900 | E9: 100 | F9: =E9*G9 -> 1800 | G9: =INDEX(Insumos!$E$5:$E$25,MATCH(A9,Insumos!$A$5:$A$25,0)) -> 18
A10: Queso mozzarella | B10: =IF(INDEX(Insumos!$B$5:$B$25,MATCH(A10,Insumos!$A$5:$A$25,0))="kg","g","und") -> g | C10: 40 | D10: =C10*G10 -> 1120 | E10: 80 | F10: =E10*G10 -> 2240 | G10: =INDEX(Insumos!$E$5:$E$25,MATCH(A10,Insumos!$A$5:$A$25,0)) -> 28
A11: Maíz tierno (escurrido) | B11: =IF(INDEX(Insumos!$B$5:$B$25,MATCH(A11,Insumos!$A$5:$A$25,0))="kg","g","und") -> g | C11: 25 | D11: =C11*G11 -> 400 | E11: 50 | F11: =E11*G11 -> 800 | G11: =INDEX(Insumos!$E$5:$E$25,MATCH(A11,Insumos!$A$5:$A$25,0)) -> 16
A12: Ripio de papa | B12: =IF(INDEX(Insumos!$B$5:$B$25,MATCH(A12,Insumos!$A$5:$A$25,0))="kg","g","und") -> g | C12: 10 | D12: =C12*G12 -> 200 | E12: 20 | F12: =E12*G12 -> 400 | G12: =INDEX(Insumos!$E$5:$E$25,MATCH(A12,Insumos!$A$5:$A$25,0)) -> 20
A13: Salsa Carnitas | B13: =IF(INDEX(Insumos!$B$5:$B$25,MATCH(A13,Insumos!$A$5:$A$25,0))="kg","g","und") -> g | C13: 35 | D13: =C13*G13 -> 509.64606 | E13: 70 | F13: =E13*G13 -> 1019.2921 | G13: =INDEX(Insumos!$E$5:$E$25,MATCH(A13,Insumos!$A$5:$A$25,0)) -> 14.561316
A14: Empaque personal | B14: =IF(INDEX(Insumos!$B$5:$B$25,MATCH(A14,Insumos!$A$5:$A$25,0))="kg","g","und") -> und | C14: 1 | D14: =C14*G14 -> 1000 | E14: 0 | F14: =E14*G14 -> 0 | G14: =INDEX(Insumos!$E$5:$E$25,MATCH(A14,Insumos!$A$5:$A$25,0)) -> 1000
A15: Empaque grande | B15: =IF(INDEX(Insumos!$B$5:$B$25,MATCH(A15,Insumos!$A$5:$A$25,0))="kg","g","und") -> und | C15: 0 | D15: =C15*G15 -> 0 | E15: 1 | F15: =E15*G15 -> 1500 | G15: =INDEX(Insumos!$E$5:$E$25,MATCH(A15,Insumos!$A$5:$A$25,0)) -> 1500
A16: TOTAL | B16: g / COP | C16: =SUMIF(B6:B15,"g",C6:C15) -> 470 | D16: =SUM(D6:D15) -> 7396.9188 | E16: =SUMIF(B6:B15,"g",E6:E15) -> 940 | F16: =SUM(F6:F15) -> 14293.838
A19: 2. La Gringa Carnitas
A20: Público de hamburguesa: queso + tocineta, el mejor margen. Ofrecer versión picante.
A21: Ingrediente | B21: Unidad | C21: Personal: cantidad | D21: Personal: costo (COP) | E21: Compartir: cantidad | F21: Compartir: costo (COP) | G21: Costo unitario (COP)
A22: Papa pastusa fresca (francesa) | B22: =IF(INDEX(Insumos!$B$5:$B$25,MATCH(A22,Insumos!$A$5:$A$25,0))="kg","g","und") -> g | C22: 250 | D22: =C22*G22 -> 727.27273 | E22: 500 | F22: =E22*G22 -> 1454.5455 | G22: =INDEX(Insumos!$E$5:$E$25,MATCH(A22,Insumos!$A$5:$A$25,0)) -> 2.9090909
A23: Aceite de fritura (porción) | B23: =IF(INDEX(Insumos!$B$5:$B$25,MATCH(A23,Insumos!$A$5:$A$25,0))="kg","g","und") -> und | C23: 1 | D23: =C23*G23 -> 500 | E23: 2 | F23: =E23*G23 -> 1000 | G23: =INDEX(Insumos!$E$5:$E$25,MATCH(A23,Insumos!$A$5:$A$25,0)) -> 500
A24: Carnitas (pernil sin hueso) | B24: =IF(INDEX(Insumos!$B$5:$B$25,MATCH(A24,Insumos!$A$5:$A$25,0))="kg","g","und") -> g | C24: 80 | D24: =C24*G24 -> 2720 | E24: 160 | F24: =E24*G24 -> 5440 | G24: =INDEX(Insumos!$E$5:$E$25,MATCH(A24,Insumos!$A$5:$A$25,0)) -> 34
A25: Salsa cheddar | B25: =IF(INDEX(Insumos!$B$5:$B$25,MATCH(A25,Insumos!$A$5:$A$25,0))="kg","g","und") -> g | C25: 50 | D25: =C25*G25 -> 1500 | E25: 100 | F25: =E25*G25 -> 3000 | G25: =INDEX(Insumos!$E$5:$E$25,MATCH(A25,Insumos!$A$5:$A$25,0)) -> 30
A26: Tocineta (peso crudo) | B26: =IF(INDEX(Insumos!$B$5:$B$25,MATCH(A26,Insumos!$A$5:$A$25,0))="kg","g","und") -> g | C26: 25 | D26: =C26*G26 -> 1000 | E26: 50 | F26: =E26*G26 -> 2000 | G26: =INDEX(Insumos!$E$5:$E$25,MATCH(A26,Insumos!$A$5:$A$25,0)) -> 40
A27: Aros de cebolla congelados | B27: =IF(INDEX(Insumos!$B$5:$B$25,MATCH(A27,Insumos!$A$5:$A$25,0))="kg","g","und") -> g | C27: 45 | D27: =C27*G27 -> 810 | E27: 90 | F27: =E27*G27 -> 1620 | G27: =INDEX(Insumos!$E$5:$E$25,MATCH(A27,Insumos!$A$5:$A$25,0)) -> 18
A28: Jalapeño encurtido | B28: =IF(INDEX(Insumos!$B$5:$B$25,MATCH(A28,Insumos!$A$5:$A$25,0))="kg","g","und") -> g | C28: 20 | D28: =C28*G28 -> 500 | E28: 40 | F28: =E28*G28 -> 1000 | G28: =INDEX(Insumos!$E$5:$E$25,MATCH(A28,Insumos!$A$5:$A$25,0)) -> 25
A29: Salsa Carnitas | B29: =IF(INDEX(Insumos!$B$5:$B$25,MATCH(A29,Insumos!$A$5:$A$25,0))="kg","g","und") -> g | C29: 40 | D29: =C29*G29 -> 582.45264 | E29: 80 | F29: =E29*G29 -> 1164.9053 | G29: =INDEX(Insumos!$E$5:$E$25,MATCH(A29,Insumos!$A$5:$A$25,0)) -> 14.561316
A30: Empaque personal | B30: =IF(INDEX(Insumos!$B$5:$B$25,MATCH(A30,Insumos!$A$5:$A$25,0))="kg","g","und") -> und | C30: 1 | D30: =C30*G30 -> 1000 | E30: 0 | F30: =E30*G30 -> 0 | G30: =INDEX(Insumos!$E$5:$E$25,MATCH(A30,Insumos!$A$5:$A$25,0)) -> 1000
A31: Empaque grande | B31: =IF(INDEX(Insumos!$B$5:$B$25,MATCH(A31,Insumos!$A$5:$A$25,0))="kg","g","und") -> und | C31: 0 | D31: =C31*G31 -> 0 | E31: 1 | F31: =E31*G31 -> 1500 | G31: =INDEX(Insumos!$E$5:$E$25,MATCH(A31,Insumos!$A$5:$A$25,0)) -> 1500
A32: TOTAL | B32: g / COP | C32: =SUMIF(B22:B31,"g",C22:C31) -> 510 | D32: =SUM(D22:D31) -> 9339.7254 | E32: =SUMIF(B22:B31,"g",E22:E31) -> 1020 | F32: =SUM(F22:F31) -> 18179.451
A35: 3. La Boyacense
A36: Plato firma: papa criolla, longaniza y queso Paipa. Lo que nadie más tiene.
A37: Ingrediente | B37: Unidad | C37: Personal: cantidad | D37: Personal: costo (COP) | E37: Compartir: cantidad | F37: Compartir: costo (COP) | G37: Costo unitario (COP)
A38: Papa criolla | B38: =IF(INDEX(Insumos!$B$5:$B$25,MATCH(A38,Insumos!$A$5:$A$25,0))="kg","g","und") -> g | C38: 200 | D38: =C38*G38 -> 1093.0526 | E38: 400 | F38: =E38*G38 -> 2186.1053 | G38: =INDEX(Insumos!$E$5:$E$25,MATCH(A38,Insumos!$A$5:$A$25,0)) -> 5.4652632
A39: Papa pastusa fresca (francesa) | B39: =IF(INDEX(Insumos!$B$5:$B$25,MATCH(A39,Insumos!$A$5:$A$25,0))="kg","g","und") -> g | C39: 150 | D39: =C39*G39 -> 436.36364 | E39: 300 | F39: =E39*G39 -> 872.72727 | G39: =INDEX(Insumos!$E$5:$E$25,MATCH(A39,Insumos!$A$5:$A$25,0)) -> 2.9090909
A40: Aceite de fritura (porción) | B40: =IF(INDEX(Insumos!$B$5:$B$25,MATCH(A40,Insumos!$A$5:$A$25,0))="kg","g","und") -> und | C40: 1 | D40: =C40*G40 -> 500 | E40: 2 | F40: =E40*G40 -> 1000 | G40: =INDEX(Insumos!$E$5:$E$25,MATCH(A40,Insumos!$A$5:$A$25,0)) -> 500
A41: Carnitas (pernil sin hueso) | B41: =IF(INDEX(Insumos!$B$5:$B$25,MATCH(A41,Insumos!$A$5:$A$25,0))="kg","g","und") -> g | C41: 60 | D41: =C41*G41 -> 2040 | E41: 120 | F41: =E41*G41 -> 4080 | G41: =INDEX(Insumos!$E$5:$E$25,MATCH(A41,Insumos!$A$5:$A$25,0)) -> 34
A42: Longaniza | B42: =IF(INDEX(Insumos!$B$5:$B$25,MATCH(A42,Insumos!$A$5:$A$25,0))="kg","g","und") -> g | C42: 60 | D42: =C42*G42 -> 1680 | E42: 120 | F42: =E42*G42 -> 3360 | G42: =INDEX(Insumos!$E$5:$E$25,MATCH(A42,Insumos!$A$5:$A$25,0)) -> 28
A43: Queso Paipa | B43: =IF(INDEX(Insumos!$B$5:$B$25,MATCH(A43,Insumos!$A$5:$A$25,0))="kg","g","und") -> g | C43: 40 | D43: =C43*G43 -> 1800 | E43: 80 | F43: =E43*G43 -> 3600 | G43: =INDEX(Insumos!$E$5:$E$25,MATCH(A43,Insumos!$A$5:$A$25,0)) -> 45
A44: Queso mozzarella | B44: =IF(INDEX(Insumos!$B$5:$B$25,MATCH(A44,Insumos!$A$5:$A$25,0))="kg","g","und") -> g | C44: 30 | D44: =C44*G44 -> 840 | E44: 60 | F44: =E44*G44 -> 1680 | G44: =INDEX(Insumos!$E$5:$E$25,MATCH(A44,Insumos!$A$5:$A$25,0)) -> 28
A45: Mazorca desgranada | B45: =IF(INDEX(Insumos!$B$5:$B$25,MATCH(A45,Insumos!$A$5:$A$25,0))="kg","g","und") -> g | C45: 30 | D45: =C45*G45 -> 360 | E45: 60 | F45: =E45*G45 -> 720 | G45: =INDEX(Insumos!$E$5:$E$25,MATCH(A45,Insumos!$A$5:$A$25,0)) -> 12
...

Sheet Insumos
A1: Insumos — precios de compra
A2: Unidad 'kg': precio por kilo; el costo es por gramo útil. Unidad 'und': precio por unidad o porción.
A4: Insumo | B4: Unidad | C4: Precio de compra (COP) | D4: Rendimiento (%) | E4: Costo por g o und útil (COP) | F4: Fuente / nota
A5: Papa pastusa fresca (francesa) | B5: kg | C5: 1600 | D5: 0.55 | E5: =IF(D5=0,0,IF(B5="kg",C5/1000/D5,C5/D5)) -> 2.9090909 | F5: Estimado; rendimiento = pelado + pérdida de agua al freír
A6: Papa criolla | B6: kg | C6: 5192 | D6: 0.95 | E6: =IF(D6=0,0,IF(B6="kg",C6/1000/D6,C6/D6)) -> 5.4652632 | F6: Agronegocios, Tunja, 04-jul-2026
A7: Carnitas (pernil sin hueso) | B7: kg | C7: 17000 | D7: 0.5 | E7: =IF(D7=0,0,IF(B7="kg",C7/1000/D7,C7/D7)) -> 34 | F7: Pernil: Agronegocios, Tunja, 04-jul-2026. Rendimiento 50% incluye manteca y condimentos; MÍDELO con tu receta
A8: Salchicha | B8: kg | C8: 18000 | D8: 1 | E8: =IF(D8=0,0,IF(B8="kg",C8/1000/D8,C8/D8)) -> 18 | F8: Estimado
A9: Longaniza | B9: kg | C9: 28000 | D9: 1 | E9: =IF(D9=0,0,IF(B9="kg",C9/1000/D9,C9/D9)) -> 28 | F9: Estimado
A10: Tocineta (peso crudo) | B10: kg | C10: 40000 | D10: 1 | E10: =IF(D10=0,0,IF(B10="kg",C10/1000/D10,C10/D10)) -> 40 | F10: Estimado; porciones en peso crudo
A11: Queso mozzarella | B11: kg | C11: 28000 | D11: 1 | E11: =IF(D11=0,0,IF(B11="kg",C11/1000/D11,C11/D11)) -> 28 | F11: Estimado
A12: Queso Paipa | B12: kg | C12: 45000 | D12: 1 | E12: =IF(D12=0,0,IF(B12="kg",C12/1000/D12,C12/D12)) -> 45 | F12: Estimado
A13: Salsa cheddar | B13: kg | C13: 30000 | D13: 1 | E13: =IF(D13=0,0,IF(B13="kg",C13/1000/D13,C13/D13)) -> 30 | F13: Estimado
A14: Maíz tierno (escurrido) | B14: kg | C14: 16000 | D14: 1 | E14: =IF(D14=0,0,IF(B14="kg",C14/1000/D14,C14/D14)) -> 16 | F14: Estimado
A15: Mazorca desgranada | B15: kg | C15: 12000 | D15: 1 | E15: =IF(D15=0,0,IF(B15="kg",C15/1000/D15,C15/D15)) -> 12 | F15: Estimado
A16: Ripio de papa | B16: kg | C16: 20000 | D16: 1 | E16: =IF(D16=0,0,IF(B16="kg",C16/1000/D16,C16/D16)) -> 20 | F16: Estimado
... A19: Piña | B19: kg | C19: 3500 | D19: 0.5 | E19: =IF(D19=0,0,IF(B19="kg",C19/1000/D19,C19/D19)) -> 7 | F19: Estimado; rendimiento sin cáscara ni corazón
A20: Salsa Carnitas | B20: kg | C20: ='Salsa Carnitas'!D16 -> 14561.316 | D20: 1 | E20: =IF(D20=0,0,IF(B20="kg",C20/1000/D20,C20/D20)) -> 14.561316 | F20: Viene de la hoja 'Salsa Carnitas'
A21: Aceite de fritura (porción) | B21: und | C21: 500 | D21: 1 | E21: =IF(D21=0,0,IF(B21="kg",C21/1000/D21,C21/D21)) -> 500 | F21: Estimado por porción personal
A22: Empaque personal | B22: und | C22: 1000 | D22: 1 | E22: =IF(D22=0,0,IF(B22="kg",C22/1000/D22,C22/D22)) -> 1000 | F22: Estimado: bandeja + tenedor + bolsa
A23: Empaque grande | B23: und | C23: 1500 | D23: 1 | E23: =IF(D23=0,0,IF(B23="kg",C23/1000/D23,C23/D23)) -> 1500 | F23: Estimado
A24: Gaseosa 250 ml | B24: und | C24: 1300 | D24: 1 | E24: =IF(D24=0,0,IF(B24="kg",C24/1000/D24,C24/D24)) -> 1300 | F24: Estimado
A25: Frasco 250 g con tapa y etiqueta | B25: und | C25: 1800 | D25: 1 | E25: =IF(D25=0,0,IF(B25="kg",C25/1000/D25,C25/D25)) -> 1800 | F25: Estimado

Sheet Salsa Carnitas
A1: Salsa Carnitas — lote de ~1 kg
A3: Ingrediente | B3: Cantidad (g) | C3: Precio por kg (COP) | D3: Costo en el lote (COP) | E3: Nota
A4: Mayonesa comercial (institucional) | B4: 840 | C4: 13000 | D4: =B4*C4/1000 -> 10920 | E4: Estimado
A5: Jalapeño encurtido escurrido | B5: 70 | C5: 25000 | D5: =B5*C5/1000 -> 1750 | E5: Estimado; mitad licuado, mitad picado
A6: Vinagre de manzana | B6: 25 | C6: 8000 | D6: =B6*C6/1000 -> 200 | E6: Estimado
A7: Salsa de soya | B7: 25 | C7: 15000 | D7: =B7*C7/1000 -> 375 | E7: Estimado
A8: Azúcar morena | B8: 12 | C8: 5000 | D8: =B8*C8/1000 -> 60 | E8: Estimado; disolver antes de mezclar
A9: Líquido del encurtido | B9: 10 | C9: 0 | D9: =B9*C9/1000 -> 0 | E9: Viene con el jalapeño
A10: Paprika ahumada | B10: 8 | C10: 80000 | D10: =B10*C10/1000 -> 640 | E10: Estimado
A11: Ajo en polvo | B11: 4 | C11: 40000 | D11: =B11*C11/1000 -> 160 | E11: Estimado
A12: Cebolla en polvo | B12: 4 | C12: 40000 | D12: =B12*C12/1000 -> 160 | E12: Estimado
A13: Pimienta negra molida | B13: 3 | C13: 80000 | D13: =B13*C13/1000 -> 240 | E13: Estimado
A14: Orégano seco | B14: 2 | C14: 50000 | D14: =B14*C14/1000 -> 100 | E14: Estimado
A15: Total del lote | B15: =SUM(B4:B14) -> 1003 | D15: =SUM(D4:D14) -> 14605
A16: Costo por kg de salsa | D16: =IF(B15=0,0,D15/B15*1000) -> 14561.316

Sheet Extras
A1: Extras, combo y salsa para llevar
A3: Extra | B3: Insumo | C3: Cantidad | D3: Costo (COP) | E3: Precio de venta (COP) | F3: % costo | G3: Ganancia (COP)
A4: Carnitas extra | B4: Carnitas (pernil sin hueso) | C4: 50 | D4: =C4*INDEX(Insumos!$E$5:$E$25,MATCH(B4,Insumos!$A$5:$A$25,0)) -> 1700 | E4: 5000 | F4: =IF(E4=0,0,D4/E4) -> 0.34 | G4: =E4-D4 -> 3300
A5: Queso Paipa extra | B5: Queso Paipa | C5: 30 | D5: =C5*INDEX(Insumos!$E$5:$E$25,MATCH(B5,Insumos!$A$5:$A$25,0)) -> 1350 | E5: 3500 | F5: =IF(E5=0,0,D5/E5) -> 0.38571429 | G5: =E5-D5 -> 2150
A6: Tocineta extra | B6: Tocineta (peso crudo) | C6: 25 | D6: =C6*INDEX(Insumos!$E$5:$E$25,MATCH(B6,Insumos!$A$5:$A$25,0)) -> 1000 | E6: 3000 | F6: =IF(E6=0,0,D6/E6) -> 0.33333333 | G6: =E6-D6 -> 2000
A7: Piña asada | B7: Piña | C7: 50 | D7: =C7*INDEX(Insumos!$E$5:$E$25,MATCH(B7,Insumos!$A$5:$A$25,0)) -> 350 | E7: 2500 | F7: =IF(E7=0,0,D7/E7) -> 0.14 | G7: =E7-D7 -> 2150
A8: Salsa Carnitas extra (2 oz) | B8: Salsa Carnitas | C8: 60 | D8: =C8*INDEX(Insumos!$E$5:$E$25,MATCH(B8,Insumos!$A$5:$A$25,0)) -> 873.67896 | E8: 2000 | F8: =IF(E8=0,0,D8/E8) -> 0.43683948 | G8: =E8-D8 -> 1126.321
A9: Versión picante (jalapeño) | B9: Jalapeño encurtido | C9: 15 | D9: =C9*INDEX(Insumos!$E$5:$E$25,MATCH(B9,Insumos!$A$5:$A$25,0)) -> 375 | E9: 1000 | F9: =IF(E9=0,0,D9/E9) -> 0.375 | G9: =E9-D9 -> 625
A10: Frasco Salsa Carnitas 250 g | B10: Salsa Carnitas + frasco | C10: 250 | D10: =C10*INDEX(Insumos!$E$5:$E$25,MATCH("Salsa Carnitas",Insumos!$A$5:$A$25,0))+INDEX(Insumos!$E$5:$E$25,MATCH("Frasco 250 g con tapa y etiqueta",Insumos!$A$5:$A$25,0)) -> 5440.329 | E10: 15000 | F10: =IF(E10=0,0,D10/E10) -> 0.3626886 | G10: =E10-D10 -> 9559.671
A11: Combo Clásica + gaseosa 250 ml | B11: Clásica personal + gaseosa | C11: 1 | D11: =Resumen!D7+INDEX(Insumos!$E$5:$E$25,MATCH("Gaseosa 250 ml",Insumos!$A$5:$A$25,0)) -> 8696.9188 | E11: 21900 | F11: =IF(E11=0,0,D11/E11) -> 0.39711958 | G11: =E11-D11 -> 13203.081
A13: Estrategia de recompra
A14: • Tarjeta de sellos: a la 8.ª compra, una Clásica gratis.
A15: • 10% con carné universitario en la Clásica, de lunes a jueves.
A16: • Día fijo de promoción (ej. 'Martes de Boyacense').
A17: • Frasco de Salsa Carnitas para llevar: ingreso extra y publicidad en casa.
A18: • Clima frío: combos con aguapanela o chocolate.
